<?xml version="1.0" ?>
<!-- =================================================================================== -->
<!-- |    This document was autogenerated by xacro from hc10_multiple_arms.xacro       | -->
<!-- |    EDITING THIS FILE BY HAND IS NOT RECOMMENDED                                 | -->
<!-- =================================================================================== -->
<robot name="hc10_multiple_arms">

  <mujoco>
        <compiler meshdir="/home/gaussian/cmu_ri_phd/phd_research/parallel_search/third_party/mujoco-2.3.2/model/hc10dtp/motoman/meshes/hc10dt_b10"
                  balanceinertia="true"
                  strippath="false"/>
  </mujoco>

  <link name="world"/>
  <link name="arm_1base">
    <visual>
      <origin rpy="0 0 0" xyz="0.038588 0 0.4833874"/>
      <geometry>
        <box size="0.6085 1.218 0.9667748"/>
      </geometry>
      <material name="Wood">
        <color rgba="0.729 0.549 0.353 1.0"/>
      </material>
    </visual>
    <collision>
      <origin rpy="0 0 0" xyz="0.038588 0 0.4833874"/>
      <geometry>
        <box size="0.6085 1.218 0.9667748"/>
      </geometry>
    </collision>
    <inertial>
      <origin rpy="0.0 0.0 0.0" xyz="0.0 0.0 0.0"/>
      <mass value="10.0"/>
      <inertia ixx="0.001" ixy="0.0" ixz="0.001" iyy="0.0" iyz="0.0" izz="0.001"/>
    </inertial>
  </link>
  <joint name="arm_1base_to_world" type="fixed">
    <parent link="world"/>
    <child link="arm_1base"/>
    <origin rpy="0.0 0.0 0.0" xyz="0.0 0.0 0.0"/>
  </joint>
  <link name="arm_1base_plate">
    <visual>
      <origin rpy="0 0 0" xyz="0 0 0.003175"/>
      <geometry>
        <box size="0.3048 0.3048 0.00635"/>
      </geometry>
      <material name="Silver">
        <color rgba="0.7529 0.7529 0.7529 1.0"/>
      </material>
    </visual>
    <collision>
      <origin rpy="0 0 0" xyz="0 0 0.003175"/>
      <geometry>
        <box size="0.3048 0.3048 0.00635"/>
      </geometry>
    </collision>
    <inertial>
      <origin rpy="0.0 0.0 0.0" xyz="0.0 0.0 0.0"/>
      <mass value="10.0"/>
      <inertia ixx="0.001" ixy="0.0" ixz="0.001" iyy="0.0" iyz="0.0" izz="0.001"/>
    </inertial>
  </link>
  <joint name="arm_1plate_to_base" type="fixed">
    <parent link="arm_1base"/>
    <child link="arm_1base_plate"/>
    <origin rpy="0.0 0.0 0.0" xyz="0.0 0.0 0.9699498000000001"/>
  </joint>
  <!-- link list -->
  <link name="arm_1base_link">
    <visual>
      <geometry>
        <mesh filename="visual/base_link.dae"/>
      </geometry>
      <material name="">
        <color rgba="0.12941176470588237 0.14901960784313725 0.7490196078431373 1.0"/>
      </material>
    </visual>
    <collision>
      <geometry>
        <mesh filename="collision/base_link.obj"/>
      </geometry>
    </collision>
  </link>
  <link name="arm_1link_1_s">
    <visual>
      <geometry>
        <mesh filename="visual/link_1_s.dae"/>
      </geometry>
      <material name="">
        <color rgba="0.12941176470588237 0.14901960784313725 0.7490196078431373 1.0"/>
      </material>
    </visual>
    <collision>
      <geometry>
        <mesh filename="collision/link_1_s.obj"/>
      </geometry>
    </collision>
  </link>
  <link name="arm_1link_2_l">
    <visual>
      <geometry>
        <mesh filename="visual/link_2_l.dae"/>
      </geometry>
      <material name="">
        <color rgba="0.12941176470588237 0.14901960784313725 0.7490196078431373 1.0"/>
      </material>
    </visual>
    <collision>
      <geometry>
        <mesh filename="collision/link_2_l.obj"/>
      </geometry>
    </collision>
  </link>
  <link name="arm_1link_3_u">
    <visual>
      <geometry>
        <mesh filename="visual/link_3_u.dae"/>
      </geometry>
      <material name="">
        <color rgba="0.12941176470588237 0.14901960784313725 0.7490196078431373 1.0"/>
      </material>
    </visual>
    <collision>
      <geometry>
        <mesh filename="collision/link_3_u.obj"/>
      </geometry>
    </collision>
  </link>
  <link name="arm_1link_4_r">
    <visual>
      <geometry>
        <mesh filename="visual/link_4_r.dae"/>
      </geometry>
      <material name="">
        <color rgba="0.12941176470588237 0.14901960784313725 0.7490196078431373 1.0"/>
      </material>
    </visual>
    <collision>
      <geometry>
        <mesh filename="collision/link_4_r.obj"/>
      </geometry>
    </collision>
  </link>
  <link name="arm_1link_5_b">
    <visual>
      <geometry>
        <mesh filename="visual/link_5_b.dae"/>
      </geometry>
      <material name="">
        <color rgba="0.12941176470588237 0.14901960784313725 0.7490196078431373 1.0"/>
      </material>
    </visual>
    <collision>
      <geometry>
        <mesh filename="collision/link_5_b.obj"/>
      </geometry>
    </collision>
  </link>
  <link name="arm_1link_6_t">
    <visual>
      <geometry>
        <mesh filename="visual/link_6_t.dae"/>
      </geometry>
      <material name="">
        <color rgba="0.12941176470588237 0.14901960784313725 0.7490196078431373 1.0"/>
      </material>
    </visual>
    <collision>
      <geometry>
        <mesh filename="collision/link_6_t.obj"/>
      </geometry>
    </collision>
  </link>
  <!-- ROS-Industrial 'tool0' frame: all-zeros tool frame -->
  <link name="arm_1tool0"/>
  <link name="arm_1TCP"/>
  <!-- end of link list -->
  <!-- joint list -->
  <joint name="arm_1joint_1_s" type="revolute">
    <parent link="arm_1base_link"/>
    <child link="arm_1link_1_s"/>
    <origin rpy="0 0 0" xyz="0 0 0.275"/>
    <axis xyz="0 0 1"/>
    <limit effort="368.48" lower="-3.141592653589793" upper="3.141592653589793" velocity="2.2689280275926285"/>
  </joint>
  <joint name="arm_1joint_2_l" type="revolute">
    <parent link="arm_1link_1_s"/>
    <child link="arm_1link_2_l"/>
    <origin rpy="0 0 0" xyz="0 0 0"/>
    <axis xyz="0 1 0"/>
    <limit effort="414.54" lower="-3.141592653589793" upper="3.141592653589793" velocity="2.2689280275926285"/>
  </joint>
  <joint name="arm_1joint_3_u" type="revolute">
    <parent link="arm_1link_2_l"/>
    <child link="arm_1link_3_u"/>
    <origin rpy="0 0 0" xyz="0 0 0.700"/>
    <axis xyz="0 -1 0"/>
    <limit effort="158.76" lower="-1.6580627893946132" upper="4.625122517784973" velocity="3.141592653589793"/>
  </joint>
  <joint name="arm_1joint_4_r" type="revolute">
    <parent link="arm_1link_3_u"/>
    <child link="arm_1link_4_r"/>
    <origin rpy="0 0 0" xyz="0.500 0 0"/>
    <axis xyz="-1 0 0"/>
    <limit effort="41.16" lower="-3.141592653589793" upper="3.141592653589793" velocity="3.141592653589793"/>
  </joint>
  <joint name="arm_1joint_5_b" type="revolute">
    <parent link="arm_1link_4_r"/>
    <child link="arm_1link_5_b"/>
    <origin rpy="0 0 0" xyz="0 0.162 0"/>
    <axis xyz="0 -1 0"/>
    <limit effort="33.32" lower="-3.141592653589793" upper="3.141592653589793" velocity="4.363323129985824"/>
  </joint>
  <joint name="arm_1joint_6_t" type="revolute">
    <parent link="arm_1link_5_b"/>
    <child link="arm_1link_6_t"/>
    <origin rpy="0 0 0" xyz="0 0 0"/>
    <axis xyz="-1 0 0"/>
    <limit effort="31.36" lower="-3.141592653589793" upper="3.141592653589793" velocity="4.363323129985824"/>
  </joint>
  <!-- end of joint list -->
  <!-- ROS-Industrial 'flange' frame: attachment point for EEF models -->
  <link name="arm_1flange"/>
  <joint name="arm_1joint_6_t-flange" type="fixed">
    <origin rpy="0 0 0" xyz="0.170 0 0"/>
    <parent link="arm_1link_6_t"/>
    <child link="arm_1flange"/>
  </joint>
  <joint name="arm_1flange-tool0" type="fixed">
    <origin rpy="3.141592653589793 -1.5707963267948966 0" xyz="0 0 0"/>
    <parent link="arm_1flange"/>
    <child link="arm_1tool0"/>
  </joint>
  <joint name="arm_1tool0-TCP" type="fixed">
    <origin rpy="0 -3.141592653589793 1.5707963267948966" xyz="0 0 0.13"/>
    <parent link="arm_1tool0"/>
    <child link="arm_1TCP"/>
  </joint>
  <!-- ROS base_link to Robot Manufacturer World Coordinates transform -->
  <!-- <link name="${prefix}base" />
    <joint name="${prefix}base_link-base" type="fixed">
      <origin xyz="0 0 0.275" rpy="0 0 0"/>
      <parent link="${prefix}base_link"/>
      <child link="${prefix}base"/>
    </joint> -->
  <!-- Robotiq Coupler -->
  <!--  + Height added by the coupler: 8mm -->
  <!--  + Reference frame: at the middle (4mm) -->
  <link name="arm_1robotiq_coupler">
    <visual>
      <geometry>
        <mesh filename="robotiq_85_coupler.obj"/>
      </geometry>
      <!-- <material name="flat_black"/> -->
    </visual>
    <collision>
      <geometry>
        <mesh filename="robotiq_85_coupler.obj"/>
      </geometry>
    </collision>
    <inertial>
      <origin rpy="0 0 0" xyz="2.073e-05   1.45286e-03  -1.1049e-03"/>
      <mass value="0.168"/>
      <inertia ixx="6.69695624e-05" ixy="5.21511788e-09" ixz="-2.74383009e-08" iyy="7.85088161e-05" iyz="5.41105193e-07" izz="1.41819717e-04"/>
    </inertial>
  </link>
  <joint name="arm_1robotiq_coupler_joint" type="fixed">
    <origin rpy="0 0 -1.5707963267948966" xyz="0 0 0.004"/>
    <parent link="arm_1tool0"/>
    <child link="arm_1robotiq_coupler"/>
  </joint>
  <!--    Do I need gazebo inteface?-->
  <!--    <gazebo reference="robotiq_coupler">-->
  <!--        <mu1>0.9</mu1>-->
  <!--        <mu2>0.9</mu2>-->
  <!--        <material>Gazebo/FlatBlack</material>-->
  <!--    </gazebo>-->
  <!-- Equivalent to the OpenRAVE manipulator denso_robotiq_85_gripper -->
  <!-- <link name="denso_robotiq_85_gripper" /> -->
  <!-- <joint name="manipulator_dummy_joint" type="fixed"> -->
  <!--   <origin xyz="0 0 0.1441" rpy="0 0 0" /> -->
  <!--   <parent link="robotiq_coupler"/> -->
  <!--   <child link="denso_robotiq_85_gripper"/> -->
  <!-- </joint> -->
  <joint name="arm_1robotiq_85_base_joint" type="fixed">
    <parent link="arm_1robotiq_coupler"/>
    <child link="arm_1robotiq_85_base_link"/>
    <origin rpy="0 -1.5707963267948966 3.141592653589793" xyz="0 0 0.004"/>
  </joint>
  <link name="arm_1robotiq_85_base_link">
    <visual>
      <geometry>
        <mesh filename="visual/robotiq_85_base_link.dae"/>
      </geometry>
    </visual>
    <collision>
      <geometry>
        <mesh filename="collision/robotiq_85_base_link.obj"/>
      </geometry>
    </collision>
    <inertial>
      <mass value="0.636951"/>
      <origin xyz="0.0 0.0 0.0"/>
      <inertia ixx="0.000380" ixy="0.000000" ixz="0.000000" iyx="0.000000" iyy="0.001110" iyz="0.000000" izx="0.000000" izy="0.000000" izz="0.001171"/>
    </inertial>
  </link>
  <joint name="arm_1robotiq_85_left_knuckle_joint" type="fixed">
    <parent link="arm_1robotiq_85_base_link"/>
    <child link="arm_1robotiq_85_left_knuckle_link"/>
    <axis xyz="0 0 1"/>
    <origin rpy="3.141592653589793 0.0 0.0" xyz="0.05490451627 0.03060114443 0.0"/>
    <limit effort="1000" lower="0.0" upper="0.80285" velocity="0.5"/>
  </joint>
  <joint name="arm_1robotiq_85_right_knuckle_joint" type="fixed">
    <parent link="arm_1robotiq_85_base_link"/>
    <child link="arm_1robotiq_85_right_knuckle_link"/>
    <axis xyz="0 0 1"/>
    <origin rpy="0.0 0.0 0.0" xyz="0.05490451627 -0.03060114443 0.0"/>
    <limit effort="1000" lower="-3.14" upper="3.14" velocity="100.0"/>
    <mimic joint="arm_1robotiq_85_left_knuckle_joint"/>
  </joint>
  <link name="arm_1robotiq_85_left_knuckle_link">
    <visual>
      <geometry>
        <mesh filename="visual/robotiq_85_knuckle_link.dae"/>
      </geometry>
    </visual>
    <collision>
      <geometry>
        <mesh filename="collision/robotiq_85_knuckle_link.obj"/>
      </geometry>
    </collision>
    <inertial>
      <mass value="0.018491"/>
      <origin xyz="0.0 0.0 0.0"/>
      <inertia ixx="0.000009" ixy="-0.000001" ixz="0.000000" iyx="-0.000001" iyy="0.000001" iyz="0.000000" izx="0.000000" izy="0.000000" izz="0.000010"/>
    </inertial>
  </link>
  <link name="arm_1robotiq_85_right_knuckle_link">
    <visual>
      <geometry>
        <mesh filename="visual/robotiq_85_knuckle_link.dae"/>
      </geometry>
    </visual>
    <collision>
      <geometry>
        <mesh filename="collision/robotiq_85_knuckle_link.obj"/>
      </geometry>
    </collision>
    <inertial>
      <mass value="0.018491"/>
      <origin xyz="0.0 0.0 0.0"/>
      <inertia ixx="0.000009" ixy="-0.000001" ixz="0.000000" iyx="-0.000001" iyy="0.000001" iyz="0.000000" izx="0.000000" izy="0.000000" izz="0.000010"/>
    </inertial>
  </link>
  <joint name="arm_1robotiq_85_left_finger_joint" type="fixed">
    <parent link="arm_1robotiq_85_left_knuckle_link"/>
    <child link="arm_1robotiq_85_left_finger_link"/>
    <origin rpy="0 0 0" xyz="-0.00408552455 -0.03148604435 0.0"/>
  </joint>
  <joint name="arm_1robotiq_85_right_finger_joint" type="fixed">
    <parent link="arm_1robotiq_85_right_knuckle_link"/>
    <child link="arm_1robotiq_85_right_finger_link"/>
    <origin rpy="0 0 0" xyz="-0.00408552455 -0.03148604435 0.0"/>
  </joint>
  <link name="arm_1robotiq_85_left_finger_link">
    <visual>
      <geometry>
        <mesh filename="visual/robotiq_85_finger_link.dae"/>
      </geometry>
    </visual>
    <collision>
      <geometry>
        <mesh filename="collision/robotiq_85_finger_link.obj"/>
      </geometry>
    </collision>
    <inertial>
      <mass value="0.027309"/>
      <origin xyz="0.0 0.0 0.0"/>
      <inertia ixx="0.000003" ixy="-0.000002" ixz="0.000000" iyx="-0.000002" iyy="0.000021" iyz="0.000000" izx="0.000000" izy="0.000000" izz="0.000020"/>
    </inertial>
  </link>
  <link name="arm_1robotiq_85_right_finger_link">
    <visual>
      <geometry>
        <mesh filename="visual/robotiq_85_finger_link.dae"/>
      </geometry>
    </visual>
    <collision>
      <geometry>
        <mesh filename="collision/robotiq_85_finger_link.obj"/>
      </geometry>
    </collision>
    <inertial>
      <mass value="0.027309"/>
      <origin xyz="0.0 0.0 0.0"/>
      <inertia ixx="0.000003" ixy="-0.000002" ixz="0.000000" iyx="-0.000002" iyy="0.000021" iyz="0.000000" izx="0.000000" izy="0.000000" izz="0.000020"/>
    </inertial>
  </link>
  <joint name="arm_1robotiq_85_left_inner_knuckle_joint" type="fixed">
    <parent link="arm_1robotiq_85_base_link"/>
    <child link="arm_1robotiq_85_left_inner_knuckle_link"/>
    <axis xyz="0 0 1"/>
    <origin rpy="3.141592653589793 0.0 0.0" xyz="0.06142 0.0127 0"/>
    <limit effort="0.1" lower="-3.14" upper="3.14" velocity="100.0"/>
    <mimic joint="arm_1robotiq_85_left_knuckle_joint" offset="0"/>
  </joint>
  <joint name="arm_1robotiq_85_right_inner_knuckle_joint" type="fixed">
    <parent link="arm_1robotiq_85_base_link"/>
    <child link="arm_1robotiq_85_right_inner_knuckle_link"/>
    <axis xyz="0 0 1"/>
    <origin rpy="0 0 0" xyz="0.06142 -0.0127 0"/>
    <limit effort="0.1" lower="-3.14" upper="3.14" velocity="100.0"/>
    <mimic joint="arm_1robotiq_85_left_knuckle_joint" offset="0"/>
  </joint>
  <link name="arm_1robotiq_85_left_inner_knuckle_link">
    <visual>
      <geometry>
        <mesh filename="visual/robotiq_85_inner_knuckle_link.dae"/>
      </geometry>
    </visual>
    <collision>
      <geometry>
        <mesh filename="collision/robotiq_85_inner_knuckle_link.obj"/>
      </geometry>
    </collision>
    <inertial>
      <mass value="0.029951"/>
      <origin xyz="0.0 0.0 0.0"/>
      <inertia ixx="0.000039" ixy="0.000000" ixz="0.000000" iyx="0.000000" iyy="0.000005" iyz="0.000000" izx="0.000000" izy="0.000000" izz="0.000035"/>
    </inertial>
  </link>
  <link name="arm_1robotiq_85_right_inner_knuckle_link">
    <visual>
      <geometry>
        <mesh filename="visual/robotiq_85_inner_knuckle_link.dae"/>
      </geometry>
    </visual>
    <collision>
      <geometry>
        <mesh filename="collision/robotiq_85_inner_knuckle_link.obj"/>
      </geometry>
    </collision>
    <inertial>
      <mass value="0.029951"/>
      <origin xyz="0.0 0.0 0.0"/>
      <inertia ixx="0.000039" ixy="0.000000" ixz="0.000000" iyx="0.000000" iyy="0.000005" iyz="0.000000" izx="0.000000" izy="0.000000" izz="0.000035"/>
    </inertial>
  </link>
  <joint name="arm_1robotiq_85_left_finger_tip_joint" type="fixed">
    <parent link="arm_1robotiq_85_left_inner_knuckle_link"/>
    <child link="arm_1robotiq_85_left_finger_tip_link"/>
    <axis xyz="0 0 1"/>
    <origin rpy="0.0 0.0 0.0" xyz="0.04303959807 -0.03759940821 0.0"/>
    <limit effort="0.1" lower="-3.14" upper="3.14" velocity="100.0"/>
    <mimic joint="arm_1robotiq_85_left_knuckle_joint" multiplier="-1"/>
  </joint>
  <joint name="arm_1robotiq_85_right_finger_tip_joint" type="fixed">
    <parent link="arm_1robotiq_85_right_inner_knuckle_link"/>
    <child link="arm_1robotiq_85_right_finger_tip_link"/>
    <axis xyz="0 0 1"/>
    <origin rpy="0.0 0.0 0.0" xyz="0.04303959807 -0.03759940821  0.0"/>
    <limit effort="0.1" lower="-3.14" upper="3.14" velocity="100.0"/>
    <mimic joint="arm_1robotiq_85_left_knuckle_joint" multiplier="-1"/>
  </joint>
  <link name="arm_1robotiq_85_left_finger_tip_link">
    <visual>
      <geometry>
        <mesh filename="visual/robotiq_85_finger_tip_link.dae"/>
      </geometry>
    </visual>
    <collision>
      <geometry>
        <mesh filename="collision/robotiq_85_finger_tip_link.obj"/>
      </geometry>
    </collision>
    <inertial>
      <mass value="0.019555"/>
      <origin xyz="0.0 0.0 0.0"/>
      <inertia ixx="0.000002" ixy="0.000000" ixz="0.000000" iyx="0.000000" iyy="0.000005" iyz="0.000000" izx="0.000000" izy="0.000000" izz="0.000006"/>
    </inertial>
  </link>
  <link name="arm_1robotiq_85_right_finger_tip_link">
    <visual>
      <geometry>
        <mesh filename="visual/robotiq_85_finger_tip_link.dae"/>
      </geometry>
    </visual>
    <collision>
      <geometry>
        <mesh filename="collision/robotiq_85_finger_tip_link.obj"/>
      </geometry>
    </collision>
    <inertial>
      <mass value="0.019555"/>
      <origin xyz="0.0 0.0 0.0"/>
      <inertia ixx="0.000002" ixy="0.000000" ixz="0.000000" iyx="0.000000" iyy="0.000005" iyz="0.000000" izx="0.000000" izy="0.000000" izz="0.000006"/>
    </inertial>
  </link>
  <!-- Improve grasping physics -->
  <gazebo reference="arm_1robotiq_85_left_finger_tip_link">
    <kp>1000000.0</kp>
    <kd>1.0</kd>
    <mu1>1.0</mu1>
    <mu2>1.0</mu2>
    <minDepth>0.001</minDepth>
  </gazebo>
  <gazebo reference="arm_1robotiq_85_right_finger_tip_link">
    <kp>1000000.0</kp>
    <kd>1.0</kd>
    <mu1>1.0</mu1>
    <mu2>1.0</mu2>
    <minDepth>0.001</minDepth>
  </gazebo>
  <transmission name="arm_1robotiq_85_left_knuckle_trans">
    <type>transmission_interface/SimpleTransmission</type>
    <joint name="arm_1robotiq_85_left_knuckle_joint">
      <!--        <hardwareInterface>PositionJointInterface</hardwareInterface>-->
      <hardwareInterface>hardware_interface/EffortJointInterface</hardwareInterface>
    </joint>
    <actuator name="arm_1robotiq_85_left_knuckle_motor">
      <mechanicalReduction>1</mechanicalReduction>
      <!--        <hardwareInterface>PositionJointInterface</hardwareInterface>-->
      <hardwareInterface>hardware_interface/EffortJointInterface</hardwareInterface>
    </actuator>
  </transmission>
  <!-- Mimic joints -->
  <gazebo>
    <plugin filename="libgazebo_mimic_joint_plugin.so" name="arm_1mimic_robotiq_85_1">
      <joint>arm_1robotiq_85_left_knuckle_joint</joint>
      <mimicJoint>arm_1robotiq_85_right_knuckle_joint</mimicJoint>
    </plugin>
    <plugin filename="libgazebo_mimic_joint_plugin.so" name="arm_1mimic_robotiq_85_2">
      <joint>arm_1robotiq_85_left_knuckle_joint</joint>
      <mimicJoint>arm_1robotiq_85_left_inner_knuckle_joint</mimicJoint>
    </plugin>
    <plugin filename="libgazebo_mimic_joint_plugin.so" name="arm_1mimic_robotiq_85_3">
      <joint>arm_1robotiq_85_left_knuckle_joint</joint>
      <mimicJoint>arm_1robotiq_85_right_inner_knuckle_joint</mimicJoint>
    </plugin>
    <plugin filename="libgazebo_mimic_joint_plugin.so" name="arm_1mimic_robotiq_85_4">
      <joint>arm_1robotiq_85_left_knuckle_joint</joint>
      <mimicJoint>arm_1robotiq_85_left_finger_tip_joint</mimicJoint>
      <multiplier>-1.0</multiplier>
      <offset>0.0</offset>
    </plugin>
    <plugin filename="libgazebo_mimic_joint_plugin.so" name="arm_1mimic_robotiq_85_5">
      <joint>arm_1robotiq_85_left_knuckle_joint</joint>
      <mimicJoint>arm_1robotiq_85_right_finger_tip_joint</mimicJoint>
      <multiplier>-1.0</multiplier>
      <offset>0.0</offset>
    </plugin>
  </gazebo>
  <!--    Add joint which connects the arm to the plate-->
  <joint name="arm_1_to_plate" type="fixed">
    <parent link="arm_1base_plate"/>
    <child link="arm_1base_link"/>
    <origin rpy="0.0 0.0 0.0" xyz="0.0 0.0 0.003175"/>
  </joint>
  <!-- Second arm -->
  <link name="arm_2base">
    <visual>
      <origin rpy="0 0 -1.5650629206864946" xyz="0.14475 0.076206 0.4714875"/>
      <geometry>
        <box size="1.220 0.6095 0.942975"/>
      </geometry>
      <material name="White">
        <color rgba="0.729 0.549 0.353 1.0"/>
      </material>
    </visual>
    <collision>
      <origin rpy="0 0 -1.5650629206864946" xyz="0.14475 0.076206 0.4714875"/>
      <geometry>
        <box size="1.220 0.6095 0.942975"/>
      </geometry>
    </collision>
    <inertial>
      <origin rpy="0.0 0.0 0.0" xyz="0.0 0.0 0.0"/>
      <mass value="100.0"/>
      <inertia ixx="0.001" ixy="0.0" ixz="0.001" iyy="0.0" iyz="0.0" izz="0.001"/>
    </inertial>
  </link>
  <joint name="arm_2base_to_world" type="fixed">
    <parent link="world"/>
    <child link="arm_2base"/>
    <origin rpy="0.0 0.0 -1.5650629206864946" xyz="0.8801946 0.770183 0.0"/>
  </joint>
  <link name="arm_2base_plate">
    <visual>
      <origin rpy="0 0 0" xyz="0 0 0.003175"/>
      <geometry>
        <box size="0.3048 0.3048 0.00635"/>
      </geometry>
      <material name="Silver">
        <color rgba="0.7529 0.7529 0.7529 1.0"/>
      </material>
    </visual>
    <collision>
      <origin rpy="0 0 0" xyz="0 0 0.003175"/>
      <geometry>
        <box size="0.3048 0.3048 0.00635"/>
      </geometry>
    </collision>
    <inertial>
      <origin rpy="0.0 0.0 0.0" xyz="0.0 0.0 0.0"/>
      <mass value="10.0"/>
      <inertia ixx="0.001" ixy="0.0" ixz="0.001" iyy="0.0" iyz="0.0" izz="0.001"/>
    </inertial>
  </link>
  <joint name="arm_2plate_to_base" type="fixed">
    <parent link="arm_2base"/>
    <child link="arm_2base_plate"/>
    <origin rpy="0.0 0.0 0.0" xyz="0.0 0.0 0.94615"/>
  </joint>
  <!-- link list -->
  <link name="arm_2base_link">
    <visual>
      <geometry>
        <mesh filename="visual/base_link.dae"/>
      </geometry>
      <material name="">
        <color rgba="0.12941176470588237 0.14901960784313725 0.7490196078431373 1.0"/>
      </material>
    </visual>
    <collision>
      <geometry>
        <mesh filename="collision/base_link.obj"/>
      </geometry>
    </collision>
  </link>
  <link name="arm_2link_1_s">
    <visual>
      <geometry>
        <mesh filename="visual/link_1_s.dae"/>
      </geometry>
      <material name="">
        <color rgba="0.12941176470588237 0.14901960784313725 0.7490196078431373 1.0"/>
      </material>
    </visual>
    <collision>
      <geometry>
        <mesh filename="collision/link_1_s.obj"/>
      </geometry>
    </collision>
  </link>
  <link name="arm_2link_2_l">
    <visual>
      <geometry>
        <mesh filename="visual/link_2_l.dae"/>
      </geometry>
      <material name="">
        <color rgba="0.12941176470588237 0.14901960784313725 0.7490196078431373 1.0"/>
      </material>
    </visual>
    <collision>
      <geometry>
        <mesh filename="collision/link_2_l.obj"/>
      </geometry>
    </collision>
  </link>
  <link name="arm_2link_3_u">
    <visual>
      <geometry>
        <mesh filename="visual/link_3_u.dae"/>
      </geometry>
      <material name="">
        <color rgba="0.12941176470588237 0.14901960784313725 0.7490196078431373 1.0"/>
      </material>
    </visual>
    <collision>
      <geometry>
        <mesh filename="collision/link_3_u.obj"/>
      </geometry>
    </collision>
  </link>
  <link name="arm_2link_4_r">
    <visual>
      <geometry>
        <mesh filename="visual/link_4_r.dae"/>
      </geometry>
      <material name="">
        <color rgba="0.12941176470588237 0.14901960784313725 0.7490196078431373 1.0"/>
      </material>
    </visual>
    <collision>
      <geometry>
        <mesh filename="collision/link_4_r.obj"/>
      </geometry>
    </collision>
  </link>
  <link name="arm_2link_5_b">
    <visual>
      <geometry>
        <mesh filename="visual/link_5_b.dae"/>
      </geometry>
      <material name="">
        <color rgba="0.12941176470588237 0.14901960784313725 0.7490196078431373 1.0"/>
      </material>
    </visual>
    <collision>
      <geometry>
        <mesh filename="collision/link_5_b.obj"/>
      </geometry>
    </collision>
  </link>
  <link name="arm_2link_6_t">
    <visual>
      <geometry>
        <mesh filename="visual/link_6_t.dae"/>
      </geometry>
      <material name="">
        <color rgba="0.12941176470588237 0.14901960784313725 0.7490196078431373 1.0"/>
      </material>
    </visual>
    <collision>
      <geometry>
        <mesh filename="collision/link_6_t.obj"/>
      </geometry>
    </collision>
  </link>
  <!-- ROS-Industrial 'tool0' frame: all-zeros tool frame -->
  <link name="arm_2tool0"/>
  <link name="arm_2TCP"/>
  <!-- end of link list -->
  <!-- joint list -->
  <joint name="arm_2joint_1_s" type="revolute">
    <parent link="arm_2base_link"/>
    <child link="arm_2link_1_s"/>
    <origin rpy="0 0 0" xyz="0 0 0.275"/>
    <axis xyz="0 0 1"/>
    <limit effort="368.48" lower="-3.141592653589793" upper="3.141592653589793" velocity="2.2689280275926285"/>
  </joint>
  <joint name="arm_2joint_2_l" type="revolute">
    <parent link="arm_2link_1_s"/>
    <child link="arm_2link_2_l"/>
    <origin rpy="0 0 0" xyz="0 0 0"/>
    <axis xyz="0 1 0"/>
    <limit effort="414.54" lower="-3.141592653589793" upper="3.141592653589793" velocity="2.2689280275926285"/>
  </joint>
  <joint name="arm_2joint_3_u" type="revolute">
    <parent link="arm_2link_2_l"/>
    <child link="arm_2link_3_u"/>
    <origin rpy="0 0 0" xyz="0 0 0.700"/>
    <axis xyz="0 -1 0"/>
    <limit effort="158.76" lower="-1.6580627893946132" upper="4.625122517784973" velocity="3.141592653589793"/>
  </joint>
  <joint name="arm_2joint_4_r" type="revolute">
    <parent link="arm_2link_3_u"/>
    <child link="arm_2link_4_r"/>
    <origin rpy="0 0 0" xyz="0.500 0 0"/>
    <axis xyz="-1 0 0"/>
    <limit effort="41.16" lower="-3.141592653589793" upper="3.141592653589793" velocity="3.141592653589793"/>
  </joint>
  <joint name="arm_2joint_5_b" type="revolute">
    <parent link="arm_2link_4_r"/>
    <child link="arm_2link_5_b"/>
    <origin rpy="0 0 0" xyz="0 0.162 0"/>
    <axis xyz="0 -1 0"/>
    <limit effort="33.32" lower="-3.141592653589793" upper="3.141592653589793" velocity="4.363323129985824"/>
  </joint>
  <joint name="arm_2joint_6_t" type="revolute">
    <parent link="arm_2link_5_b"/>
    <child link="arm_2link_6_t"/>
    <origin rpy="0 0 0" xyz="0 0 0"/>
    <axis xyz="-1 0 0"/>
    <limit effort="31.36" lower="-3.141592653589793" upper="3.141592653589793" velocity="4.363323129985824"/>
  </joint>
  <!-- end of joint list -->
  <!-- ROS-Industrial 'flange' frame: attachment point for EEF models -->
  <link name="arm_2flange"/>
  <joint name="arm_2joint_6_t-flange" type="fixed">
    <origin rpy="0 0 0" xyz="0.170 0 0"/>
    <parent link="arm_2link_6_t"/>
    <child link="arm_2flange"/>
  </joint>
  <joint name="arm_2flange-tool0" type="fixed">
    <origin rpy="3.141592653589793 -1.5707963267948966 0" xyz="0 0 0"/>
    <parent link="arm_2flange"/>
    <child link="arm_2tool0"/>
  </joint>
  <joint name="arm_2tool0-TCP" type="fixed">
    <origin rpy="0 -3.141592653589793 1.5707963267948966" xyz="0 0 0.13"/>
    <parent link="arm_2tool0"/>
    <child link="arm_2TCP"/>
  </joint>
  <!-- ROS base_link to Robot Manufacturer World Coordinates transform -->
  <!-- <link name="${prefix}base" />
    <joint name="${prefix}base_link-base" type="fixed">
      <origin xyz="0 0 0.275" rpy="0 0 0"/>
      <parent link="${prefix}base_link"/>
      <child link="${prefix}base"/>
    </joint> -->
  <!-- Robotiq Coupler -->
  <!--  + Height added by the coupler: 8mm -->
  <!--  + Reference frame: at the middle (4mm) -->
  <link name="arm_2robotiq_coupler">
    <visual>
      <geometry>
        <mesh filename="robotiq_85_coupler.obj"/>
      </geometry>
      <!-- <material name="flat_black"/> -->
    </visual>
    <collision>
      <geometry>
        <mesh filename="robotiq_85_coupler.obj"/>
      </geometry>
    </collision>
    <inertial>
      <origin rpy="0 0 0" xyz="2.073e-05   1.45286e-03  -1.1049e-03"/>
      <mass value="0.168"/>
      <inertia ixx="6.69695624e-05" ixy="5.21511788e-09" ixz="-2.74383009e-08" iyy="7.85088161e-05" iyz="5.41105193e-07" izz="1.41819717e-04"/>
    </inertial>
  </link>
  <joint name="arm_2robotiq_coupler_joint" type="fixed">
    <origin rpy="0 0 -1.5707963267948966" xyz="0 0 0.004"/>
    <parent link="arm_2tool0"/>
    <child link="arm_2robotiq_coupler"/>
  </joint>
  <!--    Do I need gazebo inteface?-->
  <!--    <gazebo reference="robotiq_coupler">-->
  <!--        <mu1>0.9</mu1>-->
  <!--        <mu2>0.9</mu2>-->
  <!--        <material>Gazebo/FlatBlack</material>-->
  <!--    </gazebo>-->
  <!-- Equivalent to the OpenRAVE manipulator denso_robotiq_85_gripper -->
  <!-- <link name="denso_robotiq_85_gripper" /> -->
  <!-- <joint name="manipulator_dummy_joint" type="fixed"> -->
  <!--   <origin xyz="0 0 0.1441" rpy="0 0 0" /> -->
  <!--   <parent link="robotiq_coupler"/> -->
  <!--   <child link="denso_robotiq_85_gripper"/> -->
  <!-- </joint> -->
  <joint name="arm_2robotiq_85_base_joint" type="fixed">
    <parent link="arm_2robotiq_coupler"/>
    <child link="arm_2robotiq_85_base_link"/>
    <origin rpy="0 -1.5707963267948966 3.141592653589793" xyz="0 0 0.004"/>
  </joint>
  <link name="arm_2robotiq_85_base_link">
    <visual>
      <geometry>
        <mesh filename="visual/robotiq_85_base_link.dae"/>
      </geometry>
    </visual>
    <collision>
      <geometry>
        <mesh filename="collision/robotiq_85_base_link.obj"/>
      </geometry>
    </collision>
    <inertial>
      <mass value="0.636951"/>
      <origin xyz="0.0 0.0 0.0"/>
      <inertia ixx="0.000380" ixy="0.000000" ixz="0.000000" iyx="0.000000" iyy="0.001110" iyz="0.000000" izx="0.000000" izy="0.000000" izz="0.001171"/>
    </inertial>
  </link>
  <joint name="arm_2robotiq_85_left_knuckle_joint" type="fixed">
    <parent link="arm_2robotiq_85_base_link"/>
    <child link="arm_2robotiq_85_left_knuckle_link"/>
    <axis xyz="0 0 1"/>
    <origin rpy="3.141592653589793 0.0 0.0" xyz="0.05490451627 0.03060114443 0.0"/>
    <limit effort="1000" lower="0.0" upper="0.80285" velocity="0.5"/>
  </joint>
  <joint name="arm_2robotiq_85_right_knuckle_joint" type="fixed">
    <parent link="arm_2robotiq_85_base_link"/>
    <child link="arm_2robotiq_85_right_knuckle_link"/>
    <axis xyz="0 0 1"/>
    <origin rpy="0.0 0.0 0.0" xyz="0.05490451627 -0.03060114443 0.0"/>
    <limit effort="1000" lower="-3.14" upper="3.14" velocity="100.0"/>
    <mimic joint="arm_2robotiq_85_left_knuckle_joint"/>
  </joint>
  <link name="arm_2robotiq_85_left_knuckle_link">
    <visual>
      <geometry>
        <mesh filename="visual/robotiq_85_knuckle_link.dae"/>
      </geometry>
    </visual>
    <collision>
      <geometry>
        <mesh filename="collision/robotiq_85_knuckle_link.obj"/>
      </geometry>
    </collision>
    <inertial>
      <mass value="0.018491"/>
      <origin xyz="0.0 0.0 0.0"/>
      <inertia ixx="0.000009" ixy="-0.000001" ixz="0.000000" iyx="-0.000001" iyy="0.000001" iyz="0.000000" izx="0.000000" izy="0.000000" izz="0.000010"/>
    </inertial>
  </link>
  <link name="arm_2robotiq_85_right_knuckle_link">
    <visual>
      <geometry>
        <mesh filename="visual/robotiq_85_knuckle_link.dae"/>
      </geometry>
    </visual>
    <collision>
      <geometry>
        <mesh filename="collision/robotiq_85_knuckle_link.obj"/>
      </geometry>
    </collision>
    <inertial>
      <mass value="0.018491"/>
      <origin xyz="0.0 0.0 0.0"/>
      <inertia ixx="0.000009" ixy="-0.000001" ixz="0.000000" iyx="-0.000001" iyy="0.000001" iyz="0.000000" izx="0.000000" izy="0.000000" izz="0.000010"/>
    </inertial>
  </link>
  <joint name="arm_2robotiq_85_left_finger_joint" type="fixed">
    <parent link="arm_2robotiq_85_left_knuckle_link"/>
    <child link="arm_2robotiq_85_left_finger_link"/>
    <origin rpy="0 0 0" xyz="-0.00408552455 -0.03148604435 0.0"/>
  </joint>
  <joint name="arm_2robotiq_85_right_finger_joint" type="fixed">
    <parent link="arm_2robotiq_85_right_knuckle_link"/>
    <child link="arm_2robotiq_85_right_finger_link"/>
    <origin rpy="0 0 0" xyz="-0.00408552455 -0.03148604435 0.0"/>
  </joint>
  <link name="arm_2robotiq_85_left_finger_link">
    <visual>
      <geometry>
        <mesh filename="visual/robotiq_85_finger_link.dae"/>
      </geometry>
    </visual>
    <collision>
      <geometry>
        <mesh filename="collision/robotiq_85_finger_link.obj"/>
      </geometry>
    </collision>
    <inertial>
      <mass value="0.027309"/>
      <origin xyz="0.0 0.0 0.0"/>
      <inertia ixx="0.000003" ixy="-0.000002" ixz="0.000000" iyx="-0.000002" iyy="0.000021" iyz="0.000000" izx="0.000000" izy="0.000000" izz="0.000020"/>
    </inertial>
  </link>
  <link name="arm_2robotiq_85_right_finger_link">
    <visual>
      <geometry>
        <mesh filename="visual/robotiq_85_finger_link.dae"/>
      </geometry>
    </visual>
    <collision>
      <geometry>
        <mesh filename="collision/robotiq_85_finger_link.obj"/>
      </geometry>
    </collision>
    <inertial>
      <mass value="0.027309"/>
      <origin xyz="0.0 0.0 0.0"/>
      <inertia ixx="0.000003" ixy="-0.000002" ixz="0.000000" iyx="-0.000002" iyy="0.000021" iyz="0.000000" izx="0.000000" izy="0.000000" izz="0.000020"/>
    </inertial>
  </link>
  <joint name="arm_2robotiq_85_left_inner_knuckle_joint" type="fixed">
    <parent link="arm_2robotiq_85_base_link"/>
    <child link="arm_2robotiq_85_left_inner_knuckle_link"/>
    <axis xyz="0 0 1"/>
    <origin rpy="3.141592653589793 0.0 0.0" xyz="0.06142 0.0127 0"/>
    <limit effort="0.1" lower="-3.14" upper="3.14" velocity="100.0"/>
    <mimic joint="arm_2robotiq_85_left_knuckle_joint" offset="0"/>
  </joint>
  <joint name="arm_2robotiq_85_right_inner_knuckle_joint" type="fixed">
    <parent link="arm_2robotiq_85_base_link"/>
    <child link="arm_2robotiq_85_right_inner_knuckle_link"/>
    <axis xyz="0 0 1"/>
    <origin rpy="0 0 0" xyz="0.06142 -0.0127 0"/>
    <limit effort="0.1" lower="-3.14" upper="3.14" velocity="100.0"/>
    <mimic joint="arm_2robotiq_85_left_knuckle_joint" offset="0"/>
  </joint>
  <link name="arm_2robotiq_85_left_inner_knuckle_link">
    <visual>
      <geometry>
        <mesh filename="visual/robotiq_85_inner_knuckle_link.dae"/>
      </geometry>
    </visual>
    <collision>
      <geometry>
        <mesh filename="collision/robotiq_85_inner_knuckle_link.obj"/>
      </geometry>
    </collision>
    <inertial>
      <mass value="0.029951"/>
      <origin xyz="0.0 0.0 0.0"/>
      <inertia ixx="0.000039" ixy="0.000000" ixz="0.000000" iyx="0.000000" iyy="0.000005" iyz="0.000000" izx="0.000000" izy="0.000000" izz="0.000035"/>
    </inertial>
  </link>
  <link name="arm_2robotiq_85_right_inner_knuckle_link">
    <visual>
      <geometry>
        <mesh filename="visual/robotiq_85_inner_knuckle_link.dae"/>
      </geometry>
    </visual>
    <collision>
      <geometry>
        <mesh filename="collision/robotiq_85_inner_knuckle_link.obj"/>
      </geometry>
    </collision>
    <inertial>
      <mass value="0.029951"/>
      <origin xyz="0.0 0.0 0.0"/>
      <inertia ixx="0.000039" ixy="0.000000" ixz="0.000000" iyx="0.000000" iyy="0.000005" iyz="0.000000" izx="0.000000" izy="0.000000" izz="0.000035"/>
    </inertial>
  </link>
  <joint name="arm_2robotiq_85_left_finger_tip_joint" type="fixed">
    <parent link="arm_2robotiq_85_left_inner_knuckle_link"/>
    <child link="arm_2robotiq_85_left_finger_tip_link"/>
    <axis xyz="0 0 1"/>
    <origin rpy="0.0 0.0 0.0" xyz="0.04303959807 -0.03759940821 0.0"/>
    <limit effort="0.1" lower="-3.14" upper="3.14" velocity="100.0"/>
    <mimic joint="arm_2robotiq_85_left_knuckle_joint" multiplier="-1"/>
  </joint>
  <joint name="arm_2robotiq_85_right_finger_tip_joint" type="fixed">
    <parent link="arm_2robotiq_85_right_inner_knuckle_link"/>
    <child link="arm_2robotiq_85_right_finger_tip_link"/>
    <axis xyz="0 0 1"/>
    <origin rpy="0.0 0.0 0.0" xyz="0.04303959807 -0.03759940821  0.0"/>
    <limit effort="0.1" lower="-3.14" upper="3.14" velocity="100.0"/>
    <mimic joint="arm_2robotiq_85_left_knuckle_joint" multiplier="-1"/>
  </joint>
  <link name="arm_2robotiq_85_left_finger_tip_link">
    <visual>
      <geometry>
        <mesh filename="visual/robotiq_85_finger_tip_link.dae"/>
      </geometry>
    </visual>
    <collision>
      <geometry>
        <mesh filename="collision/robotiq_85_finger_tip_link.obj"/>
      </geometry>
    </collision>
    <inertial>
      <mass value="0.019555"/>
      <origin xyz="0.0 0.0 0.0"/>
      <inertia ixx="0.000002" ixy="0.000000" ixz="0.000000" iyx="0.000000" iyy="0.000005" iyz="0.000000" izx="0.000000" izy="0.000000" izz="0.000006"/>
    </inertial>
  </link>
  <link name="arm_2robotiq_85_right_finger_tip_link">
    <visual>
      <geometry>
        <mesh filename="visual/robotiq_85_finger_tip_link.dae"/>
      </geometry>
    </visual>
    <collision>
      <geometry>
        <mesh filename="collision/robotiq_85_finger_tip_link.obj"/>
      </geometry>
    </collision>
    <inertial>
      <mass value="0.019555"/>
      <origin xyz="0.0 0.0 0.0"/>
      <inertia ixx="0.000002" ixy="0.000000" ixz="0.000000" iyx="0.000000" iyy="0.000005" iyz="0.000000" izx="0.000000" izy="0.000000" izz="0.000006"/>
    </inertial>
  </link>
  <!-- Improve grasping physics -->
  <gazebo reference="arm_2robotiq_85_left_finger_tip_link">
    <kp>1000000.0</kp>
    <kd>1.0</kd>
    <mu1>1.0</mu1>
    <mu2>1.0</mu2>
    <minDepth>0.001</minDepth>
  </gazebo>
  <gazebo reference="arm_2robotiq_85_right_finger_tip_link">
    <kp>1000000.0</kp>
    <kd>1.0</kd>
    <mu1>1.0</mu1>
    <mu2>1.0</mu2>
    <minDepth>0.001</minDepth>
  </gazebo>
  <transmission name="arm_2robotiq_85_left_knuckle_trans">
    <type>transmission_interface/SimpleTransmission</type>
    <joint name="arm_2robotiq_85_left_knuckle_joint">
      <!--        <hardwareInterface>PositionJointInterface</hardwareInterface>-->
      <hardwareInterface>hardware_interface/EffortJointInterface</hardwareInterface>
    </joint>
    <actuator name="arm_2robotiq_85_left_knuckle_motor">
      <mechanicalReduction>1</mechanicalReduction>
      <!--        <hardwareInterface>PositionJointInterface</hardwareInterface>-->
      <hardwareInterface>hardware_interface/EffortJointInterface</hardwareInterface>
    </actuator>
  </transmission>
  <!-- Mimic joints -->
  <gazebo>
    <plugin filename="libgazebo_mimic_joint_plugin.so" name="arm_2mimic_robotiq_85_1">
      <joint>arm_2robotiq_85_left_knuckle_joint</joint>
      <mimicJoint>arm_2robotiq_85_right_knuckle_joint</mimicJoint>
    </plugin>
    <plugin filename="libgazebo_mimic_joint_plugin.so" name="arm_2mimic_robotiq_85_2">
      <joint>arm_2robotiq_85_left_knuckle_joint</joint>
      <mimicJoint>arm_2robotiq_85_left_inner_knuckle_joint</mimicJoint>
    </plugin>
    <plugin filename="libgazebo_mimic_joint_plugin.so" name="arm_2mimic_robotiq_85_3">
      <joint>arm_2robotiq_85_left_knuckle_joint</joint>
      <mimicJoint>arm_2robotiq_85_right_inner_knuckle_joint</mimicJoint>
    </plugin>
    <plugin filename="libgazebo_mimic_joint_plugin.so" name="arm_2mimic_robotiq_85_4">
      <joint>arm_2robotiq_85_left_knuckle_joint</joint>
      <mimicJoint>arm_2robotiq_85_left_finger_tip_joint</mimicJoint>
      <multiplier>-1.0</multiplier>
      <offset>0.0</offset>
    </plugin>
    <plugin filename="libgazebo_mimic_joint_plugin.so" name="arm_2mimic_robotiq_85_5">
      <joint>arm_2robotiq_85_left_knuckle_joint</joint>
      <mimicJoint>arm_2robotiq_85_right_finger_tip_joint</mimicJoint>
      <multiplier>-1.0</multiplier>
      <offset>0.0</offset>
    </plugin>
  </gazebo>
  <!--    Add joint which connects the arm to the plate-->
  <joint name="arm_2_to_plate" type="fixed">
    <parent link="arm_2base_plate"/>
    <child link="arm_2base_link"/>
    <origin rpy="0.0 0.0 0.0" xyz="0.0 0.0 0.003175"/>
  </joint>
  <!-- Third arm -->
  <link name="arm_3base">
    <visual>
      <origin rpy="0 0 1.5650629206864946" xyz="0.135348 0.001605 0.4722749"/>
      <geometry>
        <box size="1.2214 0.6095 0.9445498"/>
      </geometry>
      <material name="White">
        <color rgba="0.729 0.549 0.353 1.0"/>
      </material>
    </visual>
    <collision>
      <origin rpy="0 0 1.5650629206864946" xyz="0.135348 0.001605 0.4722749"/>
      <geometry>
        <box size="1.2214 0.6095 0.9445498"/>
      </geometry>
    </collision>
    <inertial>
      <origin rpy="0.0 0.0 0.0" xyz="0.0 0.0 0.0"/>
      <mass value="100.0"/>
      <inertia ixx="0.001" ixy="0.0" ixz="0.001" iyy="0.0" iyz="0.0" izz="0.001"/>
    </inertial>
  </link>
  <joint name="arm_3base_to_world" type="fixed">
    <parent link="world"/>
    <child link="arm_3base"/>
    <origin rpy="0.0 0.0 1.5650629206864946" xyz="0.96210 -0.73627 0.0"/>
  </joint>
  <link name="arm_3base_plate">
    <visual>
      <origin rpy="0 0 0" xyz="0 0 0.003175"/>
      <geometry>
        <box size="0.3048 0.3048 0.00635"/>
      </geometry>
      <material name="Silver">
        <color rgba="0.7529 0.7529 0.7529 1.0"/>
      </material>
    </visual>
    <collision>
      <origin rpy="0 0 0" xyz="0 0 0.003175"/>
      <geometry>
        <box size="0.3048 0.3048 0.00635"/>
      </geometry>
    </collision>
    <inertial>
      <origin rpy="0.0 0.0 0.0" xyz="0.0 0.0 0.0"/>
      <mass value="10.0"/>
      <inertia ixx="0.001" ixy="0.0" ixz="0.001" iyy="0.0" iyz="0.0" izz="0.001"/>
    </inertial>
  </link>
  <joint name="arm_3plate_to_base" type="fixed">
    <parent link="arm_3base"/>
    <child link="arm_3base_plate"/>
    <origin rpy="0.0 0.0 0.0" xyz="0.0 0.0 0.94615"/>
  </joint>
  <!-- link list -->
  <link name="arm_3base_link">
    <visual>
      <geometry>
        <mesh filename="visual/base_link.dae"/>
      </geometry>
      <material name="">
        <color rgba="0.12941176470588237 0.14901960784313725 0.7490196078431373 1.0"/>
      </material>
    </visual>
    <collision>
      <geometry>
        <mesh filename="collision/base_link.obj"/>
      </geometry>
    </collision>
  </link>
  <link name="arm_3link_1_s">
    <visual>
      <geometry>
        <mesh filename="visual/link_1_s.dae"/>
      </geometry>
      <material name="">
        <color rgba="0.12941176470588237 0.14901960784313725 0.7490196078431373 1.0"/>
      </material>
    </visual>
    <collision>
      <geometry>
        <mesh filename="collision/link_1_s.obj"/>
      </geometry>
    </collision>
  </link>
  <link name="arm_3link_2_l">
    <visual>
      <geometry>
        <mesh filename="visual/link_2_l.dae"/>
      </geometry>
      <material name="">
        <color rgba="0.12941176470588237 0.14901960784313725 0.7490196078431373 1.0"/>
      </material>
    </visual>
    <collision>
      <geometry>
        <mesh filename="collision/link_2_l.obj"/>
      </geometry>
    </collision>
  </link>
  <link name="arm_3link_3_u">
    <visual>
      <geometry>
        <mesh filename="visual/link_3_u.dae"/>
      </geometry>
      <material name="">
        <color rgba="0.12941176470588237 0.14901960784313725 0.7490196078431373 1.0"/>
      </material>
    </visual>
    <collision>
      <geometry>
        <mesh filename="collision/link_3_u.obj"/>
      </geometry>
    </collision>
  </link>
  <link name="arm_3link_4_r">
    <visual>
      <geometry>
        <mesh filename="visual/link_4_r.dae"/>
      </geometry>
      <material name="">
        <color rgba="0.12941176470588237 0.14901960784313725 0.7490196078431373 1.0"/>
      </material>
    </visual>
    <collision>
      <geometry>
        <mesh filename="collision/link_4_r.obj"/>
      </geometry>
    </collision>
  </link>
  <link name="arm_3link_5_b">
    <visual>
      <geometry>
        <mesh filename="visual/link_5_b.dae"/>
      </geometry>
      <material name="">
        <color rgba="0.12941176470588237 0.14901960784313725 0.7490196078431373 1.0"/>
      </material>
    </visual>
    <collision>
      <geometry>
        <mesh filename="collision/link_5_b.obj"/>
      </geometry>
    </collision>
  </link>
  <link name="arm_3link_6_t">
    <visual>
      <geometry>
        <mesh filename="visual/link_6_t.dae"/>
      </geometry>
      <material name="">
        <color rgba="0.12941176470588237 0.14901960784313725 0.7490196078431373 1.0"/>
      </material>
    </visual>
    <collision>
      <geometry>
        <mesh filename="collision/link_6_t.obj"/>
      </geometry>
    </collision>
  </link>
  <!-- ROS-Industrial 'tool0' frame: all-zeros tool frame -->
  <link name="arm_3tool0"/>
  <link name="arm_3TCP"/>
  <!-- end of link list -->
  <!-- joint list -->
  <joint name="arm_3joint_1_s" type="revolute">
    <parent link="arm_3base_link"/>
    <child link="arm_3link_1_s"/>
    <origin rpy="0 0 0" xyz="0 0 0.275"/>
    <axis xyz="0 0 1"/>
    <limit effort="368.48" lower="-3.141592653589793" upper="3.141592653589793" velocity="2.2689280275926285"/>
  </joint>
  <joint name="arm_3joint_2_l" type="revolute">
    <parent link="arm_3link_1_s"/>
    <child link="arm_3link_2_l"/>
    <origin rpy="0 0 0" xyz="0 0 0"/>
    <axis xyz="0 1 0"/>
    <limit effort="414.54" lower="-3.141592653589793" upper="3.141592653589793" velocity="2.2689280275926285"/>
  </joint>
  <joint name="arm_3joint_3_u" type="revolute">
    <parent link="arm_3link_2_l"/>
    <child link="arm_3link_3_u"/>
    <origin rpy="0 0 0" xyz="0 0 0.700"/>
    <axis xyz="0 -1 0"/>
    <limit effort="158.76" lower="-1.6580627893946132" upper="4.625122517784973" velocity="3.141592653589793"/>
  </joint>
  <joint name="arm_3joint_4_r" type="revolute">
    <parent link="arm_3link_3_u"/>
    <child link="arm_3link_4_r"/>
    <origin rpy="0 0 0" xyz="0.500 0 0"/>
    <axis xyz="-1 0 0"/>
    <limit effort="41.16" lower="-3.141592653589793" upper="3.141592653589793" velocity="3.141592653589793"/>
  </joint>
  <joint name="arm_3joint_5_b" type="revolute">
    <parent link="arm_3link_4_r"/>
    <child link="arm_3link_5_b"/>
    <origin rpy="0 0 0" xyz="0 0.162 0"/>
    <axis xyz="0 -1 0"/>
    <limit effort="33.32" lower="-3.141592653589793" upper="3.141592653589793" velocity="4.363323129985824"/>
  </joint>
  <joint name="arm_3joint_6_t" type="revolute">
    <parent link="arm_3link_5_b"/>
    <child link="arm_3link_6_t"/>
    <origin rpy="0 0 0" xyz="0 0 0"/>
    <axis xyz="-1 0 0"/>
    <limit effort="31.36" lower="-3.141592653589793" upper="3.141592653589793" velocity="4.363323129985824"/>
  </joint>
  <!-- end of joint list -->
  <!-- ROS-Industrial 'flange' frame: attachment point for EEF models -->
  <link name="arm_3flange"/>
  <joint name="arm_3joint_6_t-flange" type="fixed">
    <origin rpy="0 0 0" xyz="0.170 0 0"/>
    <parent link="arm_3link_6_t"/>
    <child link="arm_3flange"/>
  </joint>
  <joint name="arm_3flange-tool0" type="fixed">
    <origin rpy="3.141592653589793 -1.5707963267948966 0" xyz="0 0 0"/>
    <parent link="arm_3flange"/>
    <child link="arm_3tool0"/>
  </joint>
  <joint name="arm_3tool0-TCP" type="fixed">
    <origin rpy="0 -3.141592653589793 1.5707963267948966" xyz="0 0 0.13"/>
    <parent link="arm_3tool0"/>
    <child link="arm_3TCP"/>
  </joint>
  <!-- ROS base_link to Robot Manufacturer World Coordinates transform -->
  <!-- <link name="${prefix}base" />
    <joint name="${prefix}base_link-base" type="fixed">
      <origin xyz="0 0 0.275" rpy="0 0 0"/>
      <parent link="${prefix}base_link"/>
      <child link="${prefix}base"/>
    </joint> -->
  <!-- Robotiq Coupler -->
  <!--  + Height added by the coupler: 8mm -->
  <!--  + Reference frame: at the middle (4mm) -->
  <link name="arm_3robotiq_coupler">
    <visual>
      <geometry>
        <mesh filename="robotiq_85_coupler.obj"/>
      </geometry>
      <!-- <material name="flat_black"/> -->
    </visual>
    <collision>
      <geometry>
        <mesh filename="robotiq_85_coupler.obj"/>
      </geometry>
    </collision>
    <inertial>
      <origin rpy="0 0 0" xyz="2.073e-05   1.45286e-03  -1.1049e-03"/>
      <mass value="0.168"/>
      <inertia ixx="6.69695624e-05" ixy="5.21511788e-09" ixz="-2.74383009e-08" iyy="7.85088161e-05" iyz="5.41105193e-07" izz="1.41819717e-04"/>
    </inertial>
  </link>
  <joint name="arm_3robotiq_coupler_joint" type="fixed">
    <origin rpy="0 0 -1.5707963267948966" xyz="0 0 0.004"/>
    <parent link="arm_3tool0"/>
    <child link="arm_3robotiq_coupler"/>
  </joint>
  <!--    Do I need gazebo inteface?-->
  <!--    <gazebo reference="robotiq_coupler">-->
  <!--        <mu1>0.9</mu1>-->
  <!--        <mu2>0.9</mu2>-->
  <!--        <material>Gazebo/FlatBlack</material>-->
  <!--    </gazebo>-->
  <!-- Equivalent to the OpenRAVE manipulator denso_robotiq_85_gripper -->
  <!-- <link name="denso_robotiq_85_gripper" /> -->
  <!-- <joint name="manipulator_dummy_joint" type="fixed"> -->
  <!--   <origin xyz="0 0 0.1441" rpy="0 0 0" /> -->
  <!--   <parent link="robotiq_coupler"/> -->
  <!--   <child link="denso_robotiq_85_gripper"/> -->
  <!-- </joint> -->
  <joint name="arm_3robotiq_85_base_joint" type="fixed">
    <parent link="arm_3robotiq_coupler"/>
    <child link="arm_3robotiq_85_base_link"/>
    <origin rpy="0 -1.5707963267948966 3.141592653589793" xyz="0 0 0.004"/>
  </joint>
  <link name="arm_3robotiq_85_base_link">
    <visual>
      <geometry>
        <mesh filename="visual/robotiq_85_base_link.dae"/>
      </geometry>
    </visual>
    <collision>
      <geometry>
        <mesh filename="collision/robotiq_85_base_link.obj"/>
      </geometry>
    </collision>
    <inertial>
      <mass value="0.636951"/>
      <origin xyz="0.0 0.0 0.0"/>
      <inertia ixx="0.000380" ixy="0.000000" ixz="0.000000" iyx="0.000000" iyy="0.001110" iyz="0.000000" izx="0.000000" izy="0.000000" izz="0.001171"/>
    </inertial>
  </link>
  <joint name="arm_3robotiq_85_left_knuckle_joint" type="fixed">
    <parent link="arm_3robotiq_85_base_link"/>
    <child link="arm_3robotiq_85_left_knuckle_link"/>
    <axis xyz="0 0 1"/>
    <origin rpy="3.141592653589793 0.0 0.0" xyz="0.05490451627 0.03060114443 0.0"/>
    <limit effort="1000" lower="0.0" upper="0.80285" velocity="0.5"/>
  </joint>
  <joint name="arm_3robotiq_85_right_knuckle_joint" type="fixed">
    <parent link="arm_3robotiq_85_base_link"/>
    <child link="arm_3robotiq_85_right_knuckle_link"/>
    <axis xyz="0 0 1"/>
    <origin rpy="0.0 0.0 0.0" xyz="0.05490451627 -0.03060114443 0.0"/>
    <limit effort="1000" lower="-3.14" upper="3.14" velocity="100.0"/>
    <mimic joint="arm_3robotiq_85_left_knuckle_joint"/>
  </joint>
  <link name="arm_3robotiq_85_left_knuckle_link">
    <visual>
      <geometry>
        <mesh filename="visual/robotiq_85_knuckle_link.dae"/>
      </geometry>
    </visual>
    <collision>
      <geometry>
        <mesh filename="collision/robotiq_85_knuckle_link.obj"/>
      </geometry>
    </collision>
    <inertial>
      <mass value="0.018491"/>
      <origin xyz="0.0 0.0 0.0"/>
      <inertia ixx="0.000009" ixy="-0.000001" ixz="0.000000" iyx="-0.000001" iyy="0.000001" iyz="0.000000" izx="0.000000" izy="0.000000" izz="0.000010"/>
    </inertial>
  </link>
  <link name="arm_3robotiq_85_right_knuckle_link">
    <visual>
      <geometry>
        <mesh filename="visual/robotiq_85_knuckle_link.dae"/>
      </geometry>
    </visual>
    <collision>
      <geometry>
        <mesh filename="collision/robotiq_85_knuckle_link.obj"/>
      </geometry>
    </collision>
    <inertial>
      <mass value="0.018491"/>
      <origin xyz="0.0 0.0 0.0"/>
      <inertia ixx="0.000009" ixy="-0.000001" ixz="0.000000" iyx="-0.000001" iyy="0.000001" iyz="0.000000" izx="0.000000" izy="0.000000" izz="0.000010"/>
    </inertial>
  </link>
  <joint name="arm_3robotiq_85_left_finger_joint" type="fixed">
    <parent link="arm_3robotiq_85_left_knuckle_link"/>
    <child link="arm_3robotiq_85_left_finger_link"/>
    <origin rpy="0 0 0" xyz="-0.00408552455 -0.03148604435 0.0"/>
  </joint>
  <joint name="arm_3robotiq_85_right_finger_joint" type="fixed">
    <parent link="arm_3robotiq_85_right_knuckle_link"/>
    <child link="arm_3robotiq_85_right_finger_link"/>
    <origin rpy="0 0 0" xyz="-0.00408552455 -0.03148604435 0.0"/>
  </joint>
  <link name="arm_3robotiq_85_left_finger_link">
    <visual>
      <geometry>
        <mesh filename="visual/robotiq_85_finger_link.dae"/>
      </geometry>
    </visual>
    <collision>
      <geometry>
        <mesh filename="collision/robotiq_85_finger_link.obj"/>
      </geometry>
    </collision>
    <inertial>
      <mass value="0.027309"/>
      <origin xyz="0.0 0.0 0.0"/>
      <inertia ixx="0.000003" ixy="-0.000002" ixz="0.000000" iyx="-0.000002" iyy="0.000021" iyz="0.000000" izx="0.000000" izy="0.000000" izz="0.000020"/>
    </inertial>
  </link>
  <link name="arm_3robotiq_85_right_finger_link">
    <visual>
      <geometry>
        <mesh filename="visual/robotiq_85_finger_link.dae"/>
      </geometry>
    </visual>
    <collision>
      <geometry>
        <mesh filename="collision/robotiq_85_finger_link.obj"/>
      </geometry>
    </collision>
    <inertial>
      <mass value="0.027309"/>
      <origin xyz="0.0 0.0 0.0"/>
      <inertia ixx="0.000003" ixy="-0.000002" ixz="0.000000" iyx="-0.000002" iyy="0.000021" iyz="0.000000" izx="0.000000" izy="0.000000" izz="0.000020"/>
    </inertial>
  </link>
  <joint name="arm_3robotiq_85_left_inner_knuckle_joint" type="fixed">
    <parent link="arm_3robotiq_85_base_link"/>
    <child link="arm_3robotiq_85_left_inner_knuckle_link"/>
    <axis xyz="0 0 1"/>
    <origin rpy="3.141592653589793 0.0 0.0" xyz="0.06142 0.0127 0"/>
    <limit effort="0.1" lower="-3.14" upper="3.14" velocity="100.0"/>
    <mimic joint="arm_3robotiq_85_left_knuckle_joint" offset="0"/>
  </joint>
  <joint name="arm_3robotiq_85_right_inner_knuckle_joint" type="fixed">
    <parent link="arm_3robotiq_85_base_link"/>
    <child link="arm_3robotiq_85_right_inner_knuckle_link"/>
    <axis xyz="0 0 1"/>
    <origin rpy="0 0 0" xyz="0.06142 -0.0127 0"/>
    <limit effort="0.1" lower="-3.14" upper="3.14" velocity="100.0"/>
    <mimic joint="arm_3robotiq_85_left_knuckle_joint" offset="0"/>
  </joint>
  <link name="arm_3robotiq_85_left_inner_knuckle_link">
    <visual>
      <geometry>
        <mesh filename="visual/robotiq_85_inner_knuckle_link.dae"/>
      </geometry>
    </visual>
    <collision>
      <geometry>
        <mesh filename="collision/robotiq_85_inner_knuckle_link.obj"/>
      </geometry>
    </collision>
    <inertial>
      <mass value="0.029951"/>
      <origin xyz="0.0 0.0 0.0"/>
      <inertia ixx="0.000039" ixy="0.000000" ixz="0.000000" iyx="0.000000" iyy="0.000005" iyz="0.000000" izx="0.000000" izy="0.000000" izz="0.000035"/>
    </inertial>
  </link>
  <link name="arm_3robotiq_85_right_inner_knuckle_link">
    <visual>
      <geometry>
        <mesh filename="visual/robotiq_85_inner_knuckle_link.dae"/>
      </geometry>
    </visual>
    <collision>
      <geometry>
        <mesh filename="collision/robotiq_85_inner_knuckle_link.obj"/>
      </geometry>
    </collision>
    <inertial>
      <mass value="0.029951"/>
      <origin xyz="0.0 0.0 0.0"/>
      <inertia ixx="0.000039" ixy="0.000000" ixz="0.000000" iyx="0.000000" iyy="0.000005" iyz="0.000000" izx="0.000000" izy="0.000000" izz="0.000035"/>
    </inertial>
  </link>
  <joint name="arm_3robotiq_85_left_finger_tip_joint" type="fixed">
    <parent link="arm_3robotiq_85_left_inner_knuckle_link"/>
    <child link="arm_3robotiq_85_left_finger_tip_link"/>
    <axis xyz="0 0 1"/>
    <origin rpy="0.0 0.0 0.0" xyz="0.04303959807 -0.03759940821 0.0"/>
    <limit effort="0.1" lower="-3.14" upper="3.14" velocity="100.0"/>
    <mimic joint="arm_3robotiq_85_left_knuckle_joint" multiplier="-1"/>
  </joint>
  <joint name="arm_3robotiq_85_right_finger_tip_joint" type="fixed">
    <parent link="arm_3robotiq_85_right_inner_knuckle_link"/>
    <child link="arm_3robotiq_85_right_finger_tip_link"/>
    <axis xyz="0 0 1"/>
    <origin rpy="0.0 0.0 0.0" xyz="0.04303959807 -0.03759940821  0.0"/>
    <limit effort="0.1" lower="-3.14" upper="3.14" velocity="100.0"/>
    <mimic joint="arm_3robotiq_85_left_knuckle_joint" multiplier="-1"/>
  </joint>
  <link name="arm_3robotiq_85_left_finger_tip_link">
    <visual>
      <geometry>
        <mesh filename="visual/robotiq_85_finger_tip_link.dae"/>
      </geometry>
    </visual>
    <collision>
      <geometry>
        <mesh filename="collision/robotiq_85_finger_tip_link.obj"/>
      </geometry>
    </collision>
    <inertial>
      <mass value="0.019555"/>
      <origin xyz="0.0 0.0 0.0"/>
      <inertia ixx="0.000002" ixy="0.000000" ixz="0.000000" iyx="0.000000" iyy="0.000005" iyz="0.000000" izx="0.000000" izy="0.000000" izz="0.000006"/>
    </inertial>
  </link>
  <link name="arm_3robotiq_85_right_finger_tip_link">
    <visual>
      <geometry>
        <mesh filename="visual/robotiq_85_finger_tip_link.dae"/>
      </geometry>
    </visual>
    <collision>
      <geometry>
        <mesh filename="collision/robotiq_85_finger_tip_link.obj"/>
      </geometry>
    </collision>
    <inertial>
      <mass value="0.019555"/>
      <origin xyz="0.0 0.0 0.0"/>
      <inertia ixx="0.000002" ixy="0.000000" ixz="0.000000" iyx="0.000000" iyy="0.000005" iyz="0.000000" izx="0.000000" izy="0.000000" izz="0.000006"/>
    </inertial>
  </link>
  <!-- Improve grasping physics -->
  <gazebo reference="arm_3robotiq_85_left_finger_tip_link">
    <kp>1000000.0</kp>
    <kd>1.0</kd>
    <mu1>1.0</mu1>
    <mu2>1.0</mu2>
    <minDepth>0.001</minDepth>
  </gazebo>
  <gazebo reference="arm_3robotiq_85_right_finger_tip_link">
    <kp>1000000.0</kp>
    <kd>1.0</kd>
    <mu1>1.0</mu1>
    <mu2>1.0</mu2>
    <minDepth>0.001</minDepth>
  </gazebo>
  <transmission name="arm_3robotiq_85_left_knuckle_trans">
    <type>transmission_interface/SimpleTransmission</type>
    <joint name="arm_3robotiq_85_left_knuckle_joint">
      <!--        <hardwareInterface>PositionJointInterface</hardwareInterface>-->
      <hardwareInterface>hardware_interface/EffortJointInterface</hardwareInterface>
    </joint>
    <actuator name="arm_3robotiq_85_left_knuckle_motor">
      <mechanicalReduction>1</mechanicalReduction>
      <!--        <hardwareInterface>PositionJointInterface</hardwareInterface>-->
      <hardwareInterface>hardware_interface/EffortJointInterface</hardwareInterface>
    </actuator>
  </transmission>
  <!-- Mimic joints -->
  <gazebo>
    <plugin filename="libgazebo_mimic_joint_plugin.so" name="arm_3mimic_robotiq_85_1">
      <joint>arm_3robotiq_85_left_knuckle_joint</joint>
      <mimicJoint>arm_3robotiq_85_right_knuckle_joint</mimicJoint>
    </plugin>
    <plugin filename="libgazebo_mimic_joint_plugin.so" name="arm_3mimic_robotiq_85_2">
      <joint>arm_3robotiq_85_left_knuckle_joint</joint>
      <mimicJoint>arm_3robotiq_85_left_inner_knuckle_joint</mimicJoint>
    </plugin>
    <plugin filename="libgazebo_mimic_joint_plugin.so" name="arm_3mimic_robotiq_85_3">
      <joint>arm_3robotiq_85_left_knuckle_joint</joint>
      <mimicJoint>arm_3robotiq_85_right_inner_knuckle_joint</mimicJoint>
    </plugin>
    <plugin filename="libgazebo_mimic_joint_plugin.so" name="arm_3mimic_robotiq_85_4">
      <joint>arm_3robotiq_85_left_knuckle_joint</joint>
      <mimicJoint>arm_3robotiq_85_left_finger_tip_joint</mimicJoint>
      <multiplier>-1.0</multiplier>
      <offset>0.0</offset>
    </plugin>
    <plugin filename="libgazebo_mimic_joint_plugin.so" name="arm_3mimic_robotiq_85_5">
      <joint>arm_3robotiq_85_left_knuckle_joint</joint>
      <mimicJoint>arm_3robotiq_85_right_finger_tip_joint</mimicJoint>
      <multiplier>-1.0</multiplier>
      <offset>0.0</offset>
    </plugin>
  </gazebo>
  <!--    Add joint which connects the arm to the plate-->
  <joint name="arm_3_to_plate" type="fixed">
    <parent link="arm_3base_plate"/>
    <child link="arm_3base_link"/>
    <origin rpy="0.0 0.0 0.0" xyz="0.0 0.0 0.003175"/>
  </joint>
  <!-- Adding the tables -->
  <link name="table_plates">
    <visual>
      <origin rpy="0 0 0" xyz="-0.114589 -0.925107 0.466725"/>
      <geometry>
        <box size="0.9150 0.61017 0.93345"/>
      </geometry>
      <material name="Wood">
        <color rgba="0.729 0.549 0.353 1.0"/>
      </material>
    </visual>
    <collision>
      <origin rpy="0 0 0" xyz="-0.114589 -0.925107 0.466725"/>
      <geometry>
        <box size="0.9150 0.61017 0.93345"/>
      </geometry>
    </collision>
    <inertial>
      <origin rpy="0.0 0.0 0.0" xyz="0.0 0.0 0.0"/>
      <mass value="100.0"/>
      <inertia ixx="0.001" ixy="0.0" ixz="0.001" iyy="0.0" iyz="0.0" izz="0.001"/>
    </inertial>
  </link>
  <joint name="table_plates_to_world" type="fixed">
    <parent link="world"/>
    <child link="table_plates"/>
    <origin rpy="0.0 0.0 0.0" xyz="0.0 0.0 0.0"/>
  </joint>
  <link name="table_parts">
    <visual>
      <origin rpy="0 0 0" xyz="-0.117171 0.904825 0.466725"/>
      <geometry>
        <box size="0.9172 0.611165 0.93345"/>
      </geometry>
      <material name="Wood">
        <color rgba="0.729 0.549 0.353 1.0"/>
      </material>
    </visual>
    <collision>
      <origin rpy="0 0 0" xyz="-0.117171 0.904825 0.466725"/>
      <geometry>
        <box size="0.9172 0.611165 0.93345"/>
      </geometry>
    </collision>
    <inertial>
      <origin rpy="0.0 0.0 0.0" xyz="0.0 0.0 0.0"/>
      <mass value="100.0"/>
      <inertia ixx="0.001" ixy="0.0" ixz="0.001" iyy="0.0" iyz="0.0" izz="0.001"/>
    </inertial>
  </link>
  <joint name="table_parts_to_world" type="fixed">
    <parent link="world"/>
    <child link="table_parts"/>
    <origin rpy="0.0 0.0 0.0" xyz="0.0 0.0 0.0"/>
  </joint>
</robot>
